<?xml version='1.0'?>

<robot name="mywheelchair" xmlns:xacro="http://www.ros.org/wiki/xacro">

  <xacro:include filename="$(find wheelchair_description)/urdf/mywheelchair.gazebo" />
  <xacro:include filename="$(find wheelchair_description)/urdf/materials.xacro" />
  <xacro:include filename="$(find wheelchair_description)/urdf/macros.xacro" />

  <xacro:property name="damp" value="0.7"/>

  <xacro:macro name="transmission_block" params="joint_name idx">
      <transmission name="tran_${idx}">
        <type>transmission_interface/SimpleTransmission</type>
        <joint name="${joint_name}">
          <hardwareInterface>hardware_interface/EffortJointInterface</hardwareInterface>
        </joint>
        <actuator name="motor__${idx}">
          <hardwareInterface>hardware_interface/EffortJointInterface</hardwareInterface>
          <mechanicalReduction>1</mechanicalReduction>
        </actuator>
      </transmission>
  </xacro:macro>

<!-- seat base -->
  <link name='seat_base'>
    <inertial>
      <mass value="13.0"/>
      <origin xyz="0 0 0.2" rpy=" 0 0 0"/>
      <box_inertia m="13" x="0.4" y="0.43" z="0.2"/>
    </inertial>
    <collision name='collision'>
      <origin xyz="0 0 0.2" rpy=" 0 0 0"/>
      <geometry>
        <box size="0.4 0.43 0.2"/>
      </geometry>
    </collision>
    <visual name='seat_base_visual'>
      <origin xyz="0 0 0.2" rpy=" 0 0 0"/>
      <geometry>
        <box size="0.4 0.43 0.2"/>
      </geometry>
    </visual>

    <collision name='left_armrest_collision'>
      <origin xyz="-0.075 0.205 0.362" rpy=" 0 0 0"/>
      <geometry>
        <box size="0.25 0.02 0.12"/>
      </geometry>
      <surface>
        <friction>
          <ode>
            <mu>0</mu>
            <mu2>0</mu2>
            <slip1>1.0</slip1>
            <slip2>1.0</slip2>
          </ode>
        </friction>
      </surface>
    </collision>
    <visual name='left_armrest_visual'>
      <origin xyz="-0.075 0.205 0.362" rpy=" 0 0 0"/>
      <geometry>
        <box size="0.25 0.02 0.12"/>
      </geometry>
    </visual>

    <collision name='right_armrest_collision'>
      <origin xyz="-0.075 -0.205 0.362" rpy=" 0 0 0"/>
      <geometry>
        <box size="0.25 0.02 0.12"/>
      </geometry>
      <surface>
        <friction>
          <ode>
            <mu>0</mu>
            <mu2>0</mu2>
            <slip1>1.0</slip1>
            <slip2>1.0</slip2>
          </ode>
        </friction>
      </surface>
    </collision>
    <visual name='right_armrest_visual'>
      <origin xyz="-0.075 -0.205 0.362" rpy=" 0 0 0"/>
      <geometry>
        <box size="0.25 0.02 0.12"/>
      </geometry>
    </visual>

    <collision name='left_caster_support_collision'>
      <origin xyz="-0.19 0.205 0.06" rpy=" 0 0 0"/>
      <geometry>
        <box size="0.02 0.02 0.076"/>
      </geometry>
      <surface>
        <friction>
          <ode>
            <mu>0</mu>
            <mu2>0</mu2>
            <slip1>1.0</slip1>
            <slip2>1.0</slip2>
          </ode>
        </friction>
      </surface>
    </collision>
    <visual name='left_caster_support_visual'>
      <origin xyz="-0.19 0.205 0.06" rpy=" 0 0 0"/>
      <geometry>
        <box size="0.02 0.02 0.076"/>
      </geometry>
    </visual>

    <collision name='left_caster_collision'>
      <origin xyz="-0.19 0.23 0.025" rpy="0 1.570795 1.570795"/>
      <geometry>
        <cylinder radius="0.025" length="0.025"/>
      </geometry>
      <surface>
        <friction>
          <ode>
            <mu>0</mu>
            <mu2>0</mu2>
            <slip1>1.0</slip1>
            <slip2>1.0</slip2>
          </ode>
        </friction>
      </surface>
    </collision>
    <visual name='left_caster_visual'>
      <origin xyz="-0.19 0.23 0.025" rpy="0 1.570795 1.570795"/>
      <geometry>
        <cylinder radius="0.025" length="0.025"/>
      </geometry>
    </visual>

    <collision name='right_caster_support_collision'>
      <origin xyz="-0.19 -0.205 0.06" rpy=" 0 0 0"/>
      <geometry>
        <box size="0.02 0.02 0.076"/>
      </geometry>
      <surface>
        <friction>
          <ode>
            <mu>0</mu>
            <mu2>0</mu2>
            <slip1>1.0</slip1>
            <slip2>1.0</slip2>
          </ode>
        </friction>
      </surface>
    </collision>
    <visual name='right_caster_support_visual'>
      <origin xyz="-0.19 -0.205 0.06" rpy=" 0 0 0"/>
      <geometry>
        <box size="0.02 0.02 0.076"/>
      </geometry>
    </visual>

    <collision name='right_caster_collision'>
      <origin xyz="-0.19 -0.23 0.025" rpy="0 1.570795 1.570795"/>
      <geometry>
        <cylinder radius="0.025" length="0.025"/>
      </geometry>
      <surface>
        <friction>
          <ode>
            <mu>0</mu>
            <mu2>0</mu2>
            <slip1>1.0</slip1>
            <slip2>1.0</slip2>
          </ode>
        </friction>
      </surface>
    </collision>
    <visual name='right_caster_visual'>
      <origin xyz="-0.19 -0.23 0.025" rpy="0 1.570795 1.570795"/>
      <geometry>
        <cylinder radius="0.025" length="0.025"/>
      </geometry>
    </visual>

    <collision name='foot_rigging_collision'>
      <origin xyz="0.25 0 0.105" rpy=" 0 0 0"/>
      <geometry>
        <box size="0.09 0.3 0.01"/>
      </geometry>
      <surface>
        <friction>
          <ode>
            <mu>0</mu>
            <mu2>0</mu2>
            <slip1>1.0</slip1>
            <slip2>1.0</slip2>
          </ode>
        </friction>
      </surface>
    </collision>
    <visual name='foot_rigging_visual'>
      <origin xyz="0.25 0 0.105" rpy=" 0 0 0"/>
      <geometry>
        <box size="0.09 0.3 0.01"/>
      </geometry>
    </visual>
  </link>

<!-- Left wheel -->
  <joint name="left_wheel_hinge" type="continuous">
    <origin xyz="0.2 0.25 0.1" rpy="0 0 0"/>
    <parent link="seat_base"/>
    <child link="left_wheel"/>
    <axis xyz="0 1 0" rpy="0 0 0"/>
    <limit effort="100" velocity="100"/>
    <joint_properties damping="0.0" friction="0.0"/>
  </joint>
  <link name="left_wheel">
    <collision name="collision">
      <origin xyz="0 0 0.0" rpy="0 1.570795 1.570795"/>
      <geometry>
        <cylinder radius="0.1" length="0.05"/>
      </geometry>
    </collision>
    <visual name="left_wheel_visual">
      <origin xyz="0 0 0.0" rpy="0 1.570795 1.570795"/>
      <geometry>
        <cylinder radius="0.1" length="0.05"/>
      </geometry>
      <material name="blue"/>
    </visual>
    <inertial>
      <origin xyz="0 0 0.0" rpy="0 1.570795 1.570795"/>
      <mass value="1"/>
      <cylinder_inertia m="1" r="0.1" h="0.05"/>
    </inertial>
  </link>

<!-- Right wheel -->
  <joint name="right_wheel_hinge" type="continuous">
    <origin xyz="0.2 -0.25 0.1" rpy="0 0 0"/>
    <parent link="seat_base"/>
    <child link="right_wheel"/>
    <axis xyz="0 1 0" rpy="0 0 0"/>
    <limit effort="100" velocity="100"/>
    <joint_properties damping="0.0" friction="0.0"/>
  </joint>
  <link name="right_wheel">
    <collision name="collision">
      <origin xyz="0 0 0.0" rpy="0 1.570795 1.570795"/>
      <geometry>
        <cylinder radius="0.1" length="0.05"/>
      </geometry>
    </collision>
    <visual name="right_wheel_visual">
      <origin xyz="0 0 0.0" rpy="0 1.570795 1.570795"/>
      <geometry>
        <cylinder radius="0.1" length="0.05"/>
      </geometry>
      <material name="blue"/>
    </visual>
    <inertial>
      <origin xyz="0 0 0.0" rpy="0 1.570795 1.570795"/>
      <mass value="1"/>
      <cylinder_inertia m="1" r="0.1" h="0.05"/>
    </inertial>
  </link>

<!-- seat back -->
  <joint name="seat_back_hinge" type="continuous">
    <origin xyz="-0.19 0 0.4" rpy="0 0 0"/>
    <parent link="seat_base"/>
    <child link="seatback"/>
    <axis xyz="0 1 0" rpy="0 0 0"/>
    <limit effort="100" velocity="0.5"/>
    <limit upper="1.570795" lower="-1.570795"/>
    <joint_properties damping="0.0" friction="0.0"/>
  </joint>

  <link name="seatback">
    <collision name="collision">
      <origin xyz="0 0 0.102" rpy="0 1.570795 1.570795"/>
      <geometry>
        <box size="0.4 0.02 0.38"/>
      </geometry>
    </collision>
    <visual name="right_wheel_visual">
      <origin xyz="0 0 0.102" rpy="0 1.570795 1.570795"/>
      <geometry>
        <box size="0.4 0.02 0.38"/>
      </geometry>
      <material name="green"/>
    </visual>
    <inertial>
      <origin xyz="0 0 0.102" rpy="0 1.570795 1.570795"/>
      <mass value="1"/>
      <box_inertia m="1" x="0.4" y="0.02" z="0.38"/>
    </inertial>
  </link>

  <xacro:transmission_block joint_name="left_wheel_hinge" idx="1"/>
  <xacro:transmission_block joint_name="right_wheel_hinge" idx="2"/>
  <xacro:transmission_block joint_name="seat_back_hinge" idx="3"/>

</robot>

